Workbook

Sheet Data
A1: Financial Statement Analysis Package (FSAP): Version 9.0
A2: Financial Reporting, Financial Statement Analysis, and Valuation: A Strategic Perspective, 9th Edition | I2: FSAP User Guides:
A3: By Jim Wahlen, Steve Baginski and Mark Bradshaw
I4: The FSAP user should only enter data in the blue-font cells shaded light green.
A6: The FSAP User Guides appear in column I to the right. | I6: The Data spreadsheet is designed for up to six years of financial statement data. The user must input the most recent year of financial statement data in column G, regardless of the number of years of data inputted.
I7: The user must conform financial statement data to the FSAP template because the spreadsheets within FSAP use the Data spreadsheet as their base. The user can, however, rename account titles as necessary to match the account titles of the particular firm. FSAP contains a number of general purpose accounts that can be renamed to fit the accounts of the particular firm (for example, Other Current Assets (1) and (2)).
I8: FSAP automatically computes the amounts of various sub-totals and totals within the Data spreadsheet. These items are shaded in gray and serve in checking the mathematical accuracy of inputted amounts. FSAP checks to ensure that total assets equal total liabilities and shareholders’ equity, that total revenues and gains minus total expenses and losses equal reported net income, and that cash flows from operating, investing, and financing activities equal the change in cash on the balance sheet. These financial data checks appear at the bottom of the Data spreadsheet. Any material non-zero amounts (that are not due to rounding) on these rows require the user to re-check amounts inputted to identify and correct the error.
A9: Analyst Name: | B9: Wahlen, Baginski & Bradshaw | I9: Insert your name in column B.
A10: Company Name: | B10: Starbucks | I10: Enter the name of the company in Column B. This name will appear on the output of all spreadsheets within FSAP.
A11: Year (Most recent in far right column.) | B11: 2010 | C11: 2011 | D11: 2012 | E11: 2013 | F11: 2014 | G11: 2015 | I11: Throughout FSAP, enter amounts for account titles listed in brackets <> as negative numbers. Except for per share amounts, be consistent with the units of the amounts entered (for example, thosands or millions).
A14: BALANCE SHEET DATA | I14: Enter Balance Sheet Data:
A15: Assets:
A16: Cash and cash equivalents | B16: 1164 | C16: 1148.1 | D16: 1188.6 | E16: 2575.7 | F16: 1708.4 | G16: 1530.1
A17: Short-term investments | B17: 285.7 | C17: 902.6 | D17: 848.4 | E17: 658.1 | F17: 135.4 | G17: 81.3
A18: Accounts and notes receivable - net | B18: 302.7 | C18: 386.5 | D18: 485.9 | E18: 561.4 | F18: 631 | G18: 719
A19: Inventories | B19: 543.3 | C19: 965.8 | D19: 1241.5 | E19: 1111.2 | F19: 1090.9 | G19: 1306.4
A20: Prepaid expenses and other current assets | B20: 156.5 | C20: 161.5 | D20: 196.5 | E20: 287.7 | F20: 285.6 | G20: 334.2
A21: Deferred income taxes - current | B21: 304.2 | C21: 230.4 | D21: 238.7 | E21: 277.3 | F21: 317.4 | G21: 381.77
A22: Other current assets (1) | I22: Other current assets (1) and (2) can be renamed and used for different types of current assets for different firms.
A23: Other current assets (2)
A24: Current Assets | B24: =SUM(B16:B23) -> 2756.4 | C24: =SUM(C16:C23) -> 3794.9 | D24: =SUM(D16:D23) -> 4199.6 | E24: =SUM(E16:E23) -> 5471.4 | F24: =SUM(F16:F23) -> 4168.7 | G24: =SUM(G16:G23) -> 4352.77 | I24: FSAP automatically computes the amount of total current assets.
A25: Long-term investments | B25: 191.8 | C25: 107 | D25: 116 | E25: 58.3 | F25: 318.4 | G25: 312.5
A26: Equity and cost investments | B26: 341.5 | C26: 372.3 | D26: 459.9 | E26: 496.5 | F26: 514.9 | G26: 352
A27: Property, plant, and equipment - at cost | B27: 5888.7 | C27: 6163.1 | D27: 6903.1 | E27: 7782.1 | F27: 8581.1 | G27: 9641.8
A28: <Accumulated depreciation> | B28: -3472.2 | C28: -3808.1 | D28: -4244.2 | E28: -4581.6 | F28: -5062.1 | G28: -5553.5
A29: Deferred income taxes - noncurrent | B29: 195.3 | C29: 156.3 | D29: 97.3 | E29: 967 | F29: 903.3 | G29: 828.9
A30: Other assets | B30: 151.2 | C30: 141.4 | D30: 144.7 | E30: =185.3 -> 185.3 | F30: =198.9 -> 198.9 | G30: =415.9 -> 415.9
A31: Other intangible assets | B31: 70.8 | C31: 111.9 | D31: 143.7 | E31: 274.8 | F31: 273.5 | G31: =302.5+217.9 -> 520.4
A32: Goodwill | B32: 262.4 | C32: 321.6 | D32: =399.1 -> 399.1 | E32: =862.9 -> 862.9 | F32: =856.2 -> 856.2 | G32: =1575.4 -> 1575.4
A33: Total Assets | B33: =SUM(B24:B32) -> 6385.9 | C33: =SUM(C24:C32) -> 7360.4 | D33: =SUM(D24:D32) -> 8219.2 | E33: =SUM(E24:E32) -> 11516.7 | F33: =SUM(F24:F32) -> 10752.9 | G33: =SUM(G24:G32) -> 12446.17 | I33: FSAP automatically computes the amount of total assets.
A35: Liabilities and Equities:
A36: Accounts payable | B36: 282.6 | C36: 540 | D36: 398.1 | E36: 491.7 | F36: 533.7 | G36: 684.2
A37: Accrued liabilities | B37: 936.2 | C37: 940.9 | D37: 1133.8 | E37: 1269.3 | F37: 1514.4 | G37: 1760.7
A38: Notes payable and short-term debt
A39: Current maturities of long-term debt
A40: Deferred tax liabilities - current
A41: Insurance Reserves | B41: 146.2 | C41: 145.6 | D41: 167.7 | E41: 178.5 | F41: 196.1 | G41: 224.8 | I41: Other current liabilities (1) and (2) can be renamed and used for different types of current liabilities for different firms.
A42: Stored value card liability | B42: 414.1 | C42: 449.3 | D42: 510.2 | E42: 653.7 | F42: 794.5 | G42: 983.8
A43: Accrued litigation charge | E43: 2784.1
A44: Current Liabilities | B44: =SUM(B36:B43) -> 1779.1 | C44: =SUM(C36:C43) -> 2075.8 | D44: =SUM(D36:D43) -> 2209.8 | E44: =SUM(E36:E43) -> 5377.3 | F44: =SUM(F36:F43) -> 3038.7 | G44: =SUM(G36:G43) -> 3653.5 | I44: FSAP automatically computes the amount of total current liabilities.
...

Sheet Analysis
A1: =Data!A1 -> Financial Statement Analysis Package (FSAP): Version 9.0
A2: =Data!A2 -> Financial Reporting, Financial Statement Analysis, and Valuation: A Strategic Perspective, 9th Edition | J2: FSAP User Guides:
A3: By James Wahlen, Steve Baginski and Mark Bradshaw
A6: The FSAP User Guides appear in column J to the right. | J6: The Analysis worksheet in FSAP automatically computes a wide array of financial statement analysis ratios using the amounts entered on the Data worksheet.
J7: The FSAP User Guides next to each row provide brief descriptions of ratio computations. See the text for more in-depth discussion of how to compute and interpret each ratio.
A9: =Data!A9 -> Analyst Name: | B9: =Data!B9 -> Wahlen, Baginski & Bradshaw
A10: =Data!A10 -> Company Name: | B10: =Data!B10 -> Starbucks
A13: DATA CHECKS
A14: =Data!A154 -> Assets - Liabilities - Equities | B14: =Data!B154 -> 0 | C14: =Data!C154 -> 0 | D14: =Data!D154 -> 0 | E14: =Data!E154 -> 0 | F14: =Data!F154 -> 0 | J14: FSAP checks the Data worksheet for an equality between total assets and total liabilities plus shareholders' equity. A non-zero amount in this row indicates a likely data input error in one or more balance sheet accounts.
A15: =Data!A155 -> Net Income (computed) - Net Income (reported) | B15: =Data!B155 -> -1.0231815e-12 | C15: =Data!C155 -> 0 | D15: =Data!D155 -> 0 | E15: =Data!E155 -> -5.5777605e-13 | F15: =Data!F155 -> 0 | J15: FSAP checks whether the net income amounts determined by revenue and expense amounts entered in the Data worksheet equal the reported amount of net income. A non-zero amount on this row likely indicates an input error in one or more income statement accounts.
A16: =Data!A156 -> Cash Changes | C16: =Data!C156 -> 1.811884e-13 | D16: =Data!D156 -> -6.1106675e-13 | E16: =Data!E156 -> 0 | F16: =Data!F156 -> 0 | J16: FSAP checks that the change in cash on the statement of cash flows equals the change in cash on the balance sheet in the Data worksheet. A non-zero amount indicates either a data input error on one or more rows of the cash flow statement or the use of a different definition of cash on the two financial statements. The user should identify the reason for and correct any non-zero amount.
A17: In the computations below, a #DIV/0! message indicates that a ratio denominator is zero.
A20: PROFITABILITY FACTORS: | J20: Profitability Factors:
A21: Year | B21: =Data!$C$11 -> 2011 | C21: =Data!$D$11 -> 2012 | D21: =Data!$E$11 -> 2013 | E21: =Data!$F$11 -> 2014 | F21: =Data!$G$11 -> 2015
A23: RETURN ON ASSETS (based on reported amounts): | J23: Return on assets measures the rate of return the firm earns per average dollar invested in assets.
A24: Profit Margin for ROA | B24: =IF(ISERROR((Data!C86+(1-Data!C142)*(-Data!C78))/Data!C65),"",(Data!C86+(1-Data!C142)*(-Data!C78))/Data!C65) -> 0.10851296 | C24: =IF(ISERROR((Data!D86+(1-Data!D142)*(-Data!D78))/Data!D65),"",(Data!D86+(1-Data!D142)*(-Data!D78))/Data!D65) -> 0.10571488 | D24: =IF(ISERROR((Data!E86+(1-Data!E142)*(-Data!E78))/Data!E65),"",(Data!E86+(1-Data!E142)*(-Data!E78))/Data!E65) -> 0.0018204994 | E24: =IF(ISERROR((Data!F86+(1-Data!F142)*(-Data!F78))/Data!F65),"",(Data!F86+(1-Data!F142)*(-Data!F78))/Data!F65) -> 0.12824603 | F24: =IF(ISERROR((Data!G86+(1-Data!G142)*(-Data!G78))/Data!G65),"",(Data!G86+(1-Data!G142)*(-Data!G78))/Data!G65) -> 0.14638464 | J24: Profit margin for ROA measures how much profitability the firm derives from its revenues. For this ratio, profitability is measured before the effects of financing costs (after tax) and minority interest in earnings.
A25: x Asset Turnover | B25: =IF(ISERROR(Data!C65/((Data!B33+Data!C33)/2)),"",Data!C65/((Data!B33+Data!C33)/2)) -> 1.7023344 | C25: =IF(ISERROR(Data!D65/((Data!C33+Data!D33)/2)),"",Data!D65/((Data!C33+Data!D33)/2)) -> 1.7072967 | D25: =IF(ISERROR(Data!E65/((Data!D33+Data!E33)/2)),"",Data!E65/((Data!D33+Data!E33)/2)) -> 1.5065743 | E25: =IF(ISERROR(Data!F65/((Data!E33+Data!F33)/2)),"",Data!F65/((Data!E33+Data!F33)/2)) -> 1.4771527 | F25: =IF(ISERROR(Data!G65/((Data!F33+Data!G33)/2)),"",Data!G65/((Data!F33+Data!G33)/2)) -> 1.6520231 | J25: Asset turnover measures how efficiently the firm uses its assets to generate sales. It measures the number of sales dollars generated per average dollar invested in assets.
A26: = Return on Assets | B26: =IF(ISERROR((Data!C86+(1-Data!C142)*(-Data!C78))/((Data!B33+Data!C33)/2)),"",(Data!C86+(1-Data!C142)*(-Data!C78))/((Data!B33+Data!C33)/2)) -> 0.18472534 | C26: =IF(ISERROR((Data!D86+(1-Data!D142)*(-Data!D78))/((Data!C33+Data!D33)/2)),"",(Data!D86+(1-Data!D142)*(-Data!D78))/((Data!C33+Data!D33)/2)) -> 0.18048666 | D26: =IF(ISERROR((Data!E86+(1-Data!E142)*(-Data!E78))/((Data!D33+Data!E33)/2)),"",(Data!E86+(1-Data!E142)*(-Data!E78))/((Data!D33+Data!E33)/2)) -> 0.0027427176 | E26: =IF(ISERROR((Data!F86+(1-Data!F142)*(-Data!F78))/((Data!E33+Data!F33)/2)),"",(Data!F86+(1-Data!F142)*(-Data!F78))/((Data!E33+Data!F33)/2)) -> 0.18943897 | F26: =IF(ISERROR((Data!G86+(1-Data!G142)*(-Data!G78))/((Data!F33+Data!G33)/2)),"",(Data!G86+(1-Data!G142)*(-Data!G78))/((Data!F33+Data!G33)/2)) -> 0.24183081 | J26: Rate of return on assets is the product of the firm's profitability and its efficiency.
A28: RETURN ON ASSETS (excluding the effects of nonrecurring items): | J28: See the preceding FSAP User Guides on ROA.
A29: Profit Margin for ROA | B29: =IF(ISERROR((Data!C86+((1-Data!C142)*-Data!C78)-Data!C144)/Data!C65),"",(Data!C86+((1-Data!C142)*-Data!C78)-Data!C144)/Data!C65) -> 0.10683524 | C29: =IF(ISERROR((Data!D86+((1-Data!D142)*-Data!D78)-Data!D144)/Data!D65),"",(Data!D86+((1-Data!D142)*-Data!D78)-Data!D144)/Data!D65) -> 0.10571488 | D29: =IF(ISERROR((Data!E86+((1-Data!E142)*-Data!E78)-Data!E144)/Data!E65),"",(Data!E86+((1-Data!E142)*-Data!E78)-Data!E144)/Data!E65) -> 0.12354575 | E29: =IF(ISERROR((Data!F86+((1-Data!F142)*-Data!F78)-Data!F144)/Data!F65),"",(Data!F86+((1-Data!F142)*-Data!F78)-Data!F144)/Data!F65) -> 0.12744774 | F29: =IF(ISERROR((Data!G86+((1-Data!G142)*-Data!G78)-Data!G144)/Data!G65),"",(Data!G86+((1-Data!G142)*-Data!G78)-Data!G144)/Data!G65) -> 0.13520798 | J29: These computations of ROA exclude the after-tax effects of nonrecurring items in income to measure the firm's persistent ROA.
A30: x Asset Turnover | B30: =IF(ISERROR(Data!C65/((Data!B33+Data!C33)/2)),"",Data!C65/((Data!B33+Data!C33)/2)) -> 1.7023344 | C30: =IF(ISERROR(Data!D65/((Data!C33+Data!D33)/2)),"",Data!D65/((Data!C33+Data!D33)/2)) -> 1.7072967 | D30: =IF(ISERROR(Data!E65/((Data!D33+Data!E33)/2)),"",Data!E65/((Data!D33+Data!E33)/2)) -> 1.5065743 | E30: =IF(ISERROR(Data!F65/((Data!E33+Data!F33)/2)),"",Data!F65/((Data!E33+Data!F33)/2)) -> 1.4771527 | F30: =IF(ISERROR(Data!G65/((Data!F33+Data!G33)/2)),"",Data!G65/((Data!F33+Data!G33)/2)) -> 1.6520231
A31: = Return on Assets | B31: =IF(ISERROR((Data!C86+((1-Data!C142)*-Data!C78)-Data!C144)/((Data!B33+Data!C33)/2)),"",(Data!C86+((1-Data!C142)*-Data!C78)-Data!C144)/((Data!B33+Data!C33)/2)) -> 0.1818693 | C31: =IF(ISERROR((Data!D86+((1-Data!D142)*-Data!D78)-Data!D144)/((Data!C33+Data!D33)/2)),"",(Data!D86+((1-Data!D142)*-Data!D78)-Data!D144)/((Data!C33+Data!D33)/2)) -> 0.18048666 | D31: =IF(ISERROR((Data!E86+((1-Data!E142)*-Data!E78)-Data!E144)/((Data!D33+Data!E33)/2)),"",(Data!E86+((1-Data!E142)*-Data!E78)-Data!E144)/((Data!D33+Data!E33)/2)) -> 0.18613086 | E31: =IF(ISERROR((Data!F86+((1-Data!F142)*-Data!F78)-Data!F144)/((Data!E33+Data!F33)/2)),"",(Data!F86+((1-Data!F142)*-Data!F78)-Data!F144)/((Data!E33+Data!F33)/2)) -> 0.18825978 | F31: =IF(ISERROR((Data!G86+((1-Data!G142)*-Data!G78)-Data!G144)/((Data!F33+Data!G33)/2)),"",(Data!G86+((1-Data!G142)*-Data!G78)-Data!G144)/((Data!F33+Data!G33)/2)) -> 0.22336671
A33: RETURN ON COMMON EQUITY (based on reported amounts): | J33: Return on common equity measures the rate of return the firm earns per average dollar in common shareholders' equity.
A34: Profit Margin for ROCE | B34: =IF(ISERROR((Data!C88-Data!C146)/Data!C65),"",(Data!C88-Data!C146)/Data!C65) -> 0.10646645 | C34: =IF(ISERROR((Data!D88-Data!D146)/Data!D65),"",(Data!D88-Data!D146)/Data!D65) -> 0.10404902 | D34: =IF(ISERROR((Data!E88-Data!E146)/Data!E65),"",(Data!E88-Data!E146)/Data!E65) -> 0.00055829096 | E34: =IF(ISERROR((Data!F88-Data!F146)/Data!F65),"",(Data!F88-Data!F146)/Data!F65) -> 0.12573718 | F34: =IF(ISERROR((Data!G88-Data!G146)/Data!G65),"",(Data!G88-Data!G146)/Data!G65) -> 0.14389413 | J34: Profit margin for ROCE measures the net profit margin per dollar of sales. Profit margin for ROCE is measured after deducting any preferred dividends from net income, in order to compute the amount of net income available to common equity shareholders.
A35: x Asset Turnover | B35: =IF(ISERROR(Data!C65/((Data!B33+Data!C33)/2)),"",Data!C65/((Data!B33+Data!C33)/2)) -> 1.7023344 | C35: =IF(ISERROR(Data!D65/((Data!C33+Data!D33)/2)),"",Data!D65/((Data!C33+Data!D33)/2)) -> 1.7072967 | D35: =IF(ISERROR(Data!E65/((Data!D33+Data!E33)/2)),"",Data!E65/((Data!D33+Data!E33)/2)) -> 1.5065743 | E35: =IF(ISERROR(Data!F65/((Data!E33+Data!F33)/2)),"",Data!F65/((Data!E33+Data!F33)/2)) -> 1.4771527 | F35: =IF(ISERROR(Data!G65/((Data!F33+Data!G33)/2)),"",Data!G65/((Data!F33+Data!G33)/2)) -> 1.6520231 | J35: Asset turnover measures how efficiently the firm uses its assets to generate sales. It measures the number of sales dollars generated per average dollar invested in assets.
A36: x Capital Structure Leverage | B36: =IF(ISERROR(((Data!B33+Data!C33)/2)/((Data!B57+Data!C57)/2)),"",((Data!B33+Data!C33)/2)/((Data!B57+Data!C57)/2)) -> 1.7055809 | C36: =IF(ISERROR(((Data!C33+Data!D33)/2)/((Data!C57+Data!D57)/2)),"",((Data!C33+Data!D33)/2)/((Data!C57+Data!D57)/2)) -> 1.6410116 | D36: =IF(ISERROR(((Data!D33+Data!E33)/2)/((Data!D57+Data!E57)/2)),"",((Data!D33+Data!E33)/2)/((Data!D57+Data!E57)/2)) -> 2.0581383 | E36: =IF(ISERROR(((Data!E33+Data!F33)/2)/((Data!E57+Data!F57)/2)),"",((Data!E33+Data!F33)/2)/((Data!E57+Data!F57)/2)) -> 2.2835463 | F36: =IF(ISERROR(((Data!F33+Data!G33)/2)/((Data!F57+Data!G57)/2)),"",((Data!F33+Data!G33)/2)/((Data!F57+Data!G57)/2)) -> 2.0918909 | J36: Capital structure leverage measures the average amount invested in assets divided by the average amount financed by common equity shareholders.
A37: = Return on Common Equity | B37: =IF(ISERROR((Data!C88-Data!C146)/((Data!B57+Data!C57)/2)),"",(Data!C88-Data!C146)/((Data!B57+Data!C57)/2)) -> 0.30912204 | C37: =IF(ISERROR((Data!D88-Data!D146)/((Data!C57+Data!D57)/2)),"",(Data!D88-Data!D146)/((Data!C57+Data!D57)/2)) -> 0.2915135 | D37: =IF(ISERROR((Data!E88-Data!E146)/((Data!D57+Data!E57)/2)),"",(Data!E88-Data!E146)/((Data!D57+Data!E57)/2)) -> 0.0017311142 | E37: =IF(ISERROR((Data!F88-Data!F146)/((Data!E57+Data!F57)/2)),"",(Data!F88-Data!F146)/((Data!E57+Data!F57)/2)) -> 0.42412994 | F37: =IF(ISERROR((Data!G88-Data!G146)/((Data!F57+Data!G57)/2)),"",(Data!G88-Data!G146)/((Data!F57+Data!G57)/2)) -> 0.49727683 | J37: Rate of return on common equity is the product of the firm's profitability, efficiency, and leverage.
A39: RETURN ON COMMON EQUITY (excluding the effects of nonrecurring items): | J39: See the preceding FSAP User Guides on ROCE.
A40: Profit Margin for ROCE | B40: =IF(ISERROR((Data!C88-Data!C146-Data!C144)/Data!C65),"",(Data!C88-Data!C146-Data!C144)/Data!C65) -> 0.10478873 | C40: =IF(ISERROR((Data!D88-Data!D146-Data!D144)/Data!D65),"",(Data!D88-Data!D146-Data!D144)/Data!D65) -> 0.10404902 | D40: =IF(ISERROR((Data!E88-Data!E146-Data!E144)/Data!E65),"",(Data!E88-Data!E146-Data!E144)/Data!E65) -> 0.12228354 | E40: =IF(ISERROR((Data!F88-Data!F146-Data!F144)/Data!F65),"",(Data!F88-Data!F146-Data!F144)/Data!F65) -> 0.1249389 | F40: =IF(ISERROR((Data!G88-Data!G146-Data!G144)/Data!G65),"",(Data!G88-Data!G146-Data!G144)/Data!G65) -> 0.13271747 | J40: These computations of ROCE exclude the after-tax effects of nonrecurring items in income to measure the firm's persistent ROCE.
A41: x Asset Turnover | B41: =IF(ISERROR(Data!C65/((Data!B33+Data!C33)/2)),"",Data!C65/((Data!B33+Data!C33)/2)) -> 1.7023344 | C41: =IF(ISERROR(Data!D65/((Data!C33+Data!D33)/2)),"",Data!D65/((Data!C33+Data!D33)/2)) -> 1.7072967 | D41: =IF(ISERROR(Data!E65/((Data!D33+Data!E33)/2)),"",Data!E65/((Data!D33+Data!E33)/2)) -> 1.5065743 | E41: =IF(ISERROR(Data!F65/((Data!E33+Data!F33)/2)),"",Data!F65/((Data!E33+Data!F33)/2)) -> 1.4771527 | F41: =IF(ISERROR(Data!G65/((Data!F33+Data!G33)/2)),"",Data!G65/((Data!F33+Data!G33)/2)) -> 1.6520231
A42: x Capital Structure Leverage | B42: =IF(ISERROR(((Data!B33+Data!C33)/2)/((Data!B57+Data!C57)/2)),"",((Data!B33+Data!C33)/2)/((Data!B57+Data!C57)/2)) -> 1.7055809 | C42: =IF(ISERROR(((Data!C33+Data!D33)/2)/((Data!C57+Data!D57)/2)),"",((Data!C33+Data!D33)/2)/((Data!C57+Data!D57)/2)) -> 1.6410116 | D42: =IF(ISERROR(((Data!D33+Data!E33)/2)/((Data!D57+Data!E57)/2)),"",((Data!D33+Data!E33)/2)/((Data!D57+Data!E57)/2)) -> 2.0581383 | E42: =IF(ISERROR(((Data!E33+Data!F33)/2)/((Data!E57+Data!F57)/2)),"",((Data!E33+Data!F33)/2)/((Data!E57+Data!F57)/2)) -> 2.2835463 | F42: =IF(ISERROR(((Data!F33+Data!G33)/2)/((Data!F57+Data!G57)/2)),"",((Data!F33+Data!G33)/2)/((Data!F57+Data!G57)/2)) -> 2.0918909
A43: = Return on Common Equity | B43: =IF(ISERROR((Data!C88-Data!C146-Data!C144)/((Data!B57+Data!C57)/2)),"",(Data!C88-Data!C146-Data!C144)/((Data!B57+Data!C57)/2)) -> 0.30425083 | C43: =IF(ISERROR((Data!D88-Data!D146-Data!D144)/((Data!C57+Data!D57)/2)),"",(Data!D88-Data!D146-Data!D144)/((Data!C57+Data!D57)/2)) -> 0.2915135 | D43: =IF(ISERROR((Data!E88-Data!E146-Data!E144)/((Data!D57+Data!E57)/2)),"",(Data!E88-Data!E146-Data!E144)/((Data!D57+Data!E57)/2)) -> 0.37916927 | E43: =IF(ISERROR((Data!F88-Data!F146-Data!F144)/((Data!E57+Data!F57)/2)),"",(Data!F88-Data!F146-Data!F144)/((Data!E57+Data!F57)/2)) -> 0.42143721 | F43: =IF(ISERROR((Data!G88-Data!G146-Data!G144)/((Data!F57+Data!G57)/2)),"",(Data!G88-Data!G146-Data!G144)/((Data!F57+Data!G57)/2)) -> 0.45865194
A45: OPERATING PERFORMANCE:
A46: Gross Profit / Revenues | B46: =IF(ISERROR(Data!C67/Data!C65),"",Data!C67/Data!C65) -> 0.57699737 | C46: =IF(ISERROR(Data!D67/Data!D65),"",Data!D67/Data!D65) -> 0.56289334 | D46: =IF(ISERROR(Data!E67/Data!E65),"",Data!E67/Data!E65) -> 0.57070116 | E46: =IF(ISERROR(Data!F67/Data!F65),"",Data!F67/Data!F65) -> 0.5829959 | F46: =IF(ISERROR(Data!G67/Data!G65),"",Data!G67/Data!G65) -> 0.59361155 | J46: Gross profit margin as a percent of revenues.
A47: Operating Profit / Revenues | B47: =IF(ISERROR(Data!C76/Data!C65),"",Data!C76/Data!C65) -> 0.14772999 | C47: =IF(ISERROR(Data!D76/Data!D65),"",Data!D76/Data!D65) -> 0.1501861 | D47: =IF(ISERROR(Data!E76/Data!E65),"",Data!E76/Data!E65) -> -0.021887696 | E47: =IF(ISERROR(Data!F76/Data!F65),"",Data!F76/Data!F65) -> 0.18732596 | F47: =IF(ISERROR(Data!G76/Data!G65),"",Data!G76/Data!G65) -> 0.18791715 | J47: Operating income as a percent of revenues.
A48: Net Income / Revenues | B48: =IF(ISERROR(Data!C88/Data!C65),"",Data!C88/Data!C65) -> 0.10646645 | C48: =IF(ISERROR(Data!D88/Data!D65),"",Data!D88/Data!D65) -> 0.10404902 | D48: =IF(ISERROR(Data!E88/Data!E65),"",Data!E88/Data!E65) -> 0.00055829096 | E48: =IF(ISERROR(Data!F88/Data!F65),"",Data!F88/Data!F65) -> 0.12573718 | F48: =IF(ISERROR(Data!G88/Data!G65),"",Data!G88/Data!G65) -> 0.14389413 | J48: Net income as a percent of revenues.
A49: Comprehensive Income / Revenues | B49: =IF(ISERROR(Data!C92/Data!C65),"",Data!C92/Data!C65) -> 0.10573143 | C49: =IF(ISERROR(Data!D92/Data!D65),"",Data!D92/Data!D65) -> 0.10234219 | D49: =IF(ISERROR(Data!E92/Data!E65),"",Data!E92/Data!E65) -> 0.0035380849 | E49: =IF(ISERROR(Data!F92/Data!F65),"",Data!F92/Data!F65) -> 0.12320189 | F49: =IF(ISERROR(Data!G92/Data!G65),"",Data!G92/Data!G65) -> 0.13379117 | J49: Comprehensive income as a percent of revenues.
A51: PERSISTENT OPERATING PERFORMANCE (excluding the effects of nonrecurring items):
A52: Persistent Operating Profit / Revenues | B52: =IF(ISERROR((Data!C76-Data!C75)/Data!C65),"",(Data!C76-Data!C75)/Data!C65) -> 0.14514888 | C52: =IF(ISERROR((Data!D76-Data!D75)/Data!D65),"",(Data!D76-Data!D75)/Data!D65) -> 0.1501861 | D52: =IF(ISERROR((Data!E76-Data!E75)/Data!E65),"",(Data!E76-Data!E75)/Data!E65) -> 0.16538192 | E52: =IF(ISERROR((Data!F76-Data!F75)/Data!F65),"",(Data!F76-Data!F75)/Data!F65) -> 0.18609784 | F52: =IF(ISERROR((Data!G76-Data!G75)/Data!G65),"",(Data!G76-Data!G75)/Data!G65) -> 0.18791715 | J52: Operating income as a percent of revenues after excluding the effects of non-recurring operating income items (such as non-recurring operating expenses and losses).
A53: Persistent Net Income / Revenues | B53: =IF(ISERROR((Data!C88-Data!C144)/Data!C65),"",(Data!C88-Data!C144)/Data!C65) -> 0.10478873 | C53: =IF(ISERROR((Data!D88-Data!D144)/Data!D65),"",(Data!D88-Data!D144)/Data!D65) -> 0.10404902 | D53: =IF(ISERROR((Data!E88-Data!E144)/Data!E65),"",(Data!E88-Data!E144)/Data!E65) -> 0.12228354 | E53: =IF(ISERROR((Data!F88-Data!F144)/Data!F65),"",(Data!F88-Data!F144)/Data!F65) -> 0.1249389 | F53: =IF(ISERROR((Data!G88-Data!G144)/Data!G65),"",(Data!G88-Data!G144)/Data!G65) -> 0.13271747 | J53: Net income as a percent of revenues, after excluding the effects of non-recurring items in income.
...

Sheet Forecasts
A1: =Data!A1 -> Financial Statement Analysis Package (FSAP): Version 9.0
A2: =Data!A2 -> Financial Reporting, Financial Statement Analysis, and Valuation: A Strategic Perspective, 9th Edition | L2: FSAP User Guides:
A3: By James Wahlen, Steve Baginski, and Mark Bradshaw
L4: The FSAP user should only enter data in the blue-font cells shaded light green.
A6: The FSAP User Guides appear in column L to the right. | L6: A Comment on Entering Forecast Assumptions:
L7: This worksheet allows the FSAP user to build forecasts of future income statements, balance sheets, and statements of cash flows. FSAP automatically enters data from the DATA spreadsheet for the most recent three years in columns B, C, and D. This worksheet allows the user flexibility to compute forecast amounts for each income statement and balance sheet account. For each account, the user should enter the forecast computations in the first row (highlighted in green with bold blue font). In the second row for each account, the user can enter forecast assumption parameters (such as growth rates or percentages) to be used in the forecast computations. In the third row for each account, the user can enter a brief explanatory note to explain the forecast assumptions. The FSAP user can also develop more detailed computations of forecast amounts in the Forecast Development worksheet, and incorporate those forecast amounts by referencing them here in the Forecasts worksheet.
A9: FSAP OUTPUT: | B9: FINANCIAL STATEMENT FORECASTS
A10: =Data!A9 -> Analyst Name: | B10: =Data!B9 -> Wahlen, Baginski & Bradshaw
A11: =Data!A10 -> Company Name: | B11: =Data!B10 -> Starbucks
B13: Row Format: | E13: Row Format:
B14: Actual Amounts | E14: Forecast Amounts | J14: Year +6 and beyond: | L14: A Comment on Forecasts for Year +6 and Beyond:
B15: Common Size Percentage | E15: Forecast assumption | I15: Long-Run Growth Rate: | J15: =Valuation!$F$29 -> 0.03 | L15: For long-run forecast amounts, the FSAP user needs to enter a long-run growth rate assumption. FSAP will automatically use that growth rate to compute forecast amounts for all of the accounts for Year +6 and beyond. The FSAP user should not alter the specific forecast computations for any of the accounts for Year +6 and beyond. The FSAP user must be sure to enter the same long run growth rate assumption as a valuation parameter in the Valuation spreadsheet.
B16: Rate of Change Percentage | E16: Forecast assumption explanation | I16: Long-Run Growth Factor: | J16: =1+$J$15 -> 1.03
B18: Actuals | E18: Forecasts | L18: A Comment on Entering Forecast Assumptions:
A19: Year | B19: =Data!E11 -> 2013 | C19: =Data!F11 -> 2014 | D19: =Data!G11 -> 2015 | E19: Year +1 | F19: Year +2 | G19: Year +3 | H19: Year +4 | I19: Year +5 | J19: Year +6 | L19: This worksheet allows the FSAP user to build forecasts of future income statements, balance sheets, and statements of cash flows. FSAP automatically enters data from the DATA spreadsheet for the most recent three years in columns B, C, and D. This worksheet allows the user flexibility to compute forecast amounts for each income statement and balance sheet account. For each account, the user should enter the forecast computations in the first row (highlighted in green with bold blue font). In the second row for each account, the user can enter forecast assumption parameters (such as growth rates or percentages) to be used in the forecast computations. In the third row for each account, the user can enter a brief explanatory note to explain the forecast assumptions. The FSAP user can also develop more detailed computations of forecast amounts in the Forecast Development worksheet, and incorporate those forecast amounts by referencing them here in the Forecasts worksheet.
A20: INCOME STATEMENT
A21: =Data!A65 -> Revenues | B21: =Data!E65 -> 14866.8 | C21: =Data!F65 -> 16447.8 | D21: =Data!G65 -> 19162.7 | E21: ='Forecast Development'!E25 -> 21678.346 | F21: ='Forecast Development'!F25 -> 23670.508 | G21: ='Forecast Development'!G25 -> 26294.167 | H21: ='Forecast Development'!H25 -> 29159.361 | I21: ='Forecast Development'!I25 -> 32286.726 | J21: =I21*$J$16 -> 33255.328 | L21: Income Statement Default Assumptions:
A22: common size | B22: =B21/B$21 -> 1 | C22: =C21/C$21 -> 1 | D22: =D21/D$21 -> 1 | E22: =E21/D21-1 -> 0.13127829 | F22: =F21/E21-1 -> 0.091896381 | G22: =G21/F21-1 -> 0.11084083 | H22: =H21/G21-1 -> 0.10896692 | I22: =I21/H21-1 -> 0.1072508 | L22: The FSAP Forecasts worksheet defaults to assume that each income statement line item will remain the same percent of total revenues as in the most current year. The FSAP user must either accept this default as a reasonable expectation or override it and enter more reasonable forecast assumptions.
A23: rate of change | C23: =IF(ISERROR(C21/B21-1),"",C21/B21-1) -> 0.10634434 | D23: =IF(ISERROR(D21/C21-1),"",D21/C21-1) -> 0.16506159 | E23: See Forecast Development worksheet for details of revenues forecasts.
A24: =Data!A66 -> <Cost of sales and occupancy expense> | B24: =Data!E66 -> -6382.3 | C24: =Data!F66 -> -6858.8 | D24: =Data!G66 -> -7787.5 | E24: =-'Forecast Development'!E264 -> -8653.4939 | F24: =-'Forecast Development'!F264 -> -9390.3551 | G24: =-'Forecast Development'!G264 -> -10336.688 | H24: =-'Forecast Development'!H264 -> -11358.676 | I24: =-'Forecast Development'!I264 -> -12461.948 | J24: =I24*$J$16 -> -12835.807
A25: common size | B25: =B24/B$21 -> -0.42929884 | C25: =C24/C$21 -> -0.4170041 | D25: =D24/D$21 -> -0.40638845 | E25: =E24/E21 -> -0.39917684 | F25: =F24/F21 -> -0.39671117 | G25: =G24/G21 -> -0.39311716 | H25: =H24/H21 -> -0.38953789 | I25: =I24/I21 -> -0.38597745
A26: rate of change | C26: =IF(ISERROR(C24/B24-1),"",C24/B24-1) -> 0.074659605 | D26: =IF(ISERROR(D24/C24-1),"",D24/C24-1) -> 0.13540269 | E26: See Forecast Development worksheet.
A27: =Data!A67 -> Gross Profit | B27: =B21+B24 -> 8484.5 | C27: =C21+C24 -> 9589 | D27: =D21+D24 -> 11375.2 | E27: =E21+E24 -> 13024.853 | F27: =F21+F24 -> 14280.153 | G27: =G21+G24 -> 15957.479 | H27: =H21+H24 -> 17800.685 | I27: =I21+I24 -> 19824.778 | J27: =J21+J24 -> 20419.521
A28: common size | B28: =B27/B$21 -> 0.57070116 | C28: =C27/C$21 -> 0.5829959 | D28: =D27/D$21 -> 0.59361155 | E28: =E27/E$21 -> 0.60082316 | F28: =F27/F$21 -> 0.60328883 | G28: =G27/G$21 -> 0.60688284 | H28: =H27/H$21 -> 0.61046211 | I28: =I27/I$21 -> 0.61402255 | J28: =J27/J$21 -> 0.61402255
A29: rate of change | C29: =IF(ISERROR(C27/B27-1),"",C27/B27-1) -> 0.13017856 | D29: =IF(ISERROR(D27/C27-1),"",D27/C27-1) -> 0.18627594 | E29: =IF(ISERROR(E27/D27-1),"",E27/D27-1) -> 0.14502185 | F29: =IF(ISERROR(F27/E27-1),"",F27/E27-1) -> 0.096377325 | G29: =IF(ISERROR(G27/F27-1),"",G27/F27-1) -> 0.11745852 | H29: =IF(ISERROR(H27/G27-1),"",H27/G27-1) -> 0.11550737 | I29: =IF(ISERROR(I27/H27-1),"",I27/H27-1) -> 0.11370869
A31: =Data!A68 -> <Store Operating Expenses> | B31: =Data!E68 -> -4286.1 | C31: =Data!F68 -> -4638.2 | D31: =Data!G68 -> -5411.1 | E31: ='Forecast Development'!E32*E32 -> -5997.2468 | F31: ='Forecast Development'!F32*F32 -> -6497.6152 | G31: ='Forecast Development'!G32*G32 -> -7162.8271 | H31: ='Forecast Development'!H32*H32 -> -7883.6352 | I31: ='Forecast Development'!I32*I32 -> -8664.2241 | J31: =I31*$J$16 -> -8924.1508
A32: common size | B32: =B31/B$21 -> -0.2883001 | C32: =C31/C$21 -> -0.28199516 | D32: =D31/D$21 -> -0.2823767 | E32: -0.35 | F32: -0.348 | G32: -0.346 | H32: -0.344 | I32: -0.342
A33: rate of change | C33: =IF(ISERROR(C31/B31-1),"",C31/B31-1) -> 0.082149273 | D33: =IF(ISERROR(D31/C31-1),"",D31/C31-1) -> 0.16663792 | E33: Assume slight decline in store operating expense as a percent of company-operated store revenues.
A34: =Data!A69 -> <Other Operating Expenses> | B34: =Data!E69 -> -431.8 | C34: =Data!F69 -> -457.3 | D34: =Data!G69 -> -522.4 | E34: =('Forecast Development'!E39+'Forecast Development'!E46)*Forecasts!E35 -> -590.63621 | F34: =('Forecast Development'!F39+'Forecast Development'!F46)*Forecasts!F35 -> -649.89599 | G34: =('Forecast Development'!G39+'Forecast Development'!G46)*Forecasts!G35 -> -727.00605 | H34: =('Forecast Development'!H39+'Forecast Development'!H46)*Forecasts!H35 -> -811.43621 | I34: =('Forecast Development'!I39+'Forecast Development'!I46)*Forecasts!I35 -> -903.85587 | J34: =I34*$J$16 -> -930.97154
A35: common size | B35: =B34/B$21 -> -0.029044583 | C35: =C34/C$21 -> -0.02780311 | D35: =D34/D$21 -> -0.027261294 | E35: -0.13 | F35: =E35 -> -0.13 | G35: =F35 -> -0.13 | H35: =G35 -> -0.13 | I35: =H35 -> -0.13
A36: rate of change | C36: =IF(ISERROR(C34/B34-1),"",C34/B34-1) -> 0.059055118 | D36: =IF(ISERROR(D34/C34-1),"",D34/C34-1) -> 0.14235731 | E36: Assume steady percentage of licensed, CPG, Foodservice, and other revenues.
A37: =Data!A70 -> <Depreciation and Amortization> | B37: =Data!E70 -> -621.4 | C37: =Data!F70 -> -709.6 | D37: =Data!G70 -> -893.9 | E37: =-'Forecast Development'!E228*0.95 -> -1048.971 | F37: =-'Forecast Development'!F228*0.95 -> -1191.471 | G37: =-'Forecast Development'!G228*0.95 -> -1362.471 | H37: =-'Forecast Development'!H228*0.95 -> -1561.971 | I37: =-'Forecast Development'!I228*0.95 -> -1094.001 | J37: =I37*$J$16 -> -1126.821
A38: common size | B38: =B37/B$21 -> -0.041797831 | C38: =C37/C$21 -> -0.043142548 | D38: =D37/D$21 -> -0.046647915
A39: rate of change | C39: =IF(ISERROR(C37/B37-1),"",C37/B37-1) -> 0.14193756 | D39: =IF(ISERROR(D37/C37-1),"",D37/C37-1) -> 0.25972379 | E39: Amounts from depreciation schedule, Forecast Development worksheet.
A40: =Data!A71 -> <General and Administrative Expenses> | B40: =Data!E71 -> -937.9 | C40: =Data!F71 -> -991.3 | D40: =Data!G71 -> -1196.7 | E40: =E$21*E41 -> -1300.7008 | F40: =F$21*F41 -> -1420.2305 | G40: =G$21*G41 -> -1577.65 | H40: =H$21*H41 -> -1749.5617 | I40: =I$21*I41 -> -1937.2036 | J40: =I40*$J$16 -> -1995.3197
A41: common size | B41: =B40/B$21 -> -0.063086878 | C41: =C40/C$21 -> -0.060269459 | D41: =D40/D$21 -> -0.062449446 | E41: -0.06 | F41: =E41 -> -0.06 | G41: =F41 -> -0.06 | H41: =G41 -> -0.06 | I41: =H41 -> -0.06
A42: rate of change | C42: =IF(ISERROR(C40/B40-1),"",C40/B40-1) -> 0.056935707 | D42: =IF(ISERROR(D40/C40-1),"",D40/C40-1) -> 0.20720266 | E42: Assume steady state relative to revenues.
A43: =Data!A72 -> Other operating expenses (1) | B43: =Data!E72 -> 0 | C43: =Data!F72 -> 0 | D43: =Data!G72 -> 0 | E43: =E$21*E44 -> 0 | F43: =F$21*F44 -> 0 | G43: =G$21*G44 -> 0 | H43: =H$21*H44 -> 0 | I43: =I$21*I44 -> 0 | J43: =I43*$J$16 -> 0
A44: common size | B44: =B43/B$21 -> 0 | C44: =C43/C$21 -> 0 | D44: =D43/D$21 -> 0 | E44: 0 | F44: =E44 -> 0 | G44: =F44 -> 0 | H44: =G44 -> 0 | I44: =H44 -> 0
A45: rate of change | C45: =IF(ISERROR(C43/B43-1),"",C43/B43-1) | D45: =IF(ISERROR(D43/C43-1),"",D43/C43-1) | E45: Explain assumptions.
...

Sheet Forecast Development
A1: =Data!A1 -> Financial Statement Analysis Package (FSAP): Version 9.0
A2: =Data!A2 -> Financial Reporting, Financial Statement Analysis, and Valuation: A Strategic Perspective, 9th Edition | K2: FSAP User Guides:
A3: By James Wahlen, Steve Baginski and Mark Bradshaw
K4: The FSAP user should only enter data in the blue-font cells shaded light green.
A6: The FSAP User Guides appear in column K to the right. | K6: Forecast Development:
K7: This Forecast Development spreadsheet provides work space in which the analyst can:
K8: - build detailed Revenues revenue forecasts
K9: - build forecasts of capital expenditures, property, plant and equipment, depreciation expense, and accumulated depreciation.
K10: - build detailed forecasts of other financial statement amounts.
A11: Analyst Name: | B11: =Data!B9 -> Wahlen, Baginski & Bradshaw
A12: Company Name: | B12: =Data!B10 -> Starbucks
K13: It is not necessary to use this spreadsheet to build financial statement forecasts in the FSAP Forecasts
K14: spreadsheet. If you use this spreadsheet to build more detailed forecasts, the you will need to link these
K15: forecast amounts to the appropriate cells in the financial statements in the FSAP Forecasts spreadsheet.
A16: Revenue Forecast Development
B18: Actuals | E18: Forecasts
A19: Year | B19: =Forecasts!B19 -> 2013 | C19: =Forecasts!C19 -> 2014 | D19: =Forecasts!D19 -> 2015 | E19: =Forecasts!E19 -> Year +1 | F19: =Forecasts!F19 -> Year +2 | G19: =Forecasts!G19 -> Year +3 | H19: =Forecasts!H19 -> Year +4 | I19: =Forecasts!I19 -> Year +5
A21: Net Revenues (in millions):
A22: Company-operated stores | B22: =B32 -> 11802.7 | C22: =C32 -> 12983 | D22: =D32 -> 15203.2 | E22: =E32 -> 17134.991 | F22: =F32 -> 18671.308 | G22: =G32 -> 20701.812 | H22: =H32 -> 22917.544 | I22: =I32 -> 25333.988
A23: Licensed stores | B23: =B39 -> 1351 | C23: =C39 -> 1583.5 | D23: =D39 -> 1856 | E23: =E39 -> 2185.0084 | F23: =F39 -> 2453.965 | G23: =G39 -> 2792.5958 | H23: =H39 -> 3162.0826 | I23: =I39 -> 3565.0297
A24: CPG, foodservice and other | B24: =B46 -> 1713.1 | C24: =C46 -> 1881.3 | D24: =D46 -> 2103.5 | E24: =E46 -> 2358.3471 | F24: =F46 -> 2545.235 | G24: =G46 -> 2799.7585 | H24: =H46 -> 3079.7344 | I24: =I46 -> 3387.7078
A25: Total Net Revenues | B25: =SUM(B22:B24) -> 14866.8 | C25: =SUM(C22:C24) -> 16447.8 | D25: =SUM(D22:D24) -> 19162.7 | E25: =SUM(E22:E24) -> 21678.346 | F25: =SUM(F22:F24) -> 23670.508 | G25: =SUM(G22:G24) -> 26294.167 | H25: =SUM(H22:H24) -> 29159.361 | I25: =SUM(I22:I24) -> 32286.726 | K25: This revenue forecast development schedule was developed specifically for Starbucks. FSAP users who wish to develop detailed revenues forecasts of other firms should adapt this schedule as necessary to incorporate the other firms' various soruces of revenue.
A26: rate of change | C26: =C25/B25-1 -> 0.10634434 | D26: =D25/C25-1 -> 0.16506159 | E26: =E25/D25-1 -> 0.13127829 | F26: =F25/E25-1 -> 0.091896381 | G26: =G25/F25-1 -> 0.11084083 | H26: =H25/G25-1 -> 0.10896692 | I26: =I25/H25-1 -> 0.1072508
E27: Implied revenue growth rates.
A29: Summary: Revenues by Segment and Type: | E29: Starbucks: Revenue Forecasts by Segment and Type
B30: =B19 -> 2013 | C30: =C19 -> 2014 | D30: =D19 -> 2015 | E30: =E19 -> Year +1 | F30: =F19 -> Year +2 | G30: =G19 -> Year +3 | H30: =H19 -> Year +4 | I30: =I19 -> Year +5
A32: Company-operated stores | B32: =B63 -> 11802.7 | C32: =C63 -> 12983 | D32: =D63 -> 15203.2 | E32: =E63 -> 17134.991 | F32: =F63 -> 18671.308 | G32: =G63 -> 20701.812 | H32: =H63 -> 22917.544 | I32: =I63 -> 25333.988
A33: Growth rates | C33: =C32/B32-1 -> 0.10000254 | D33: =D32/C32-1 -> 0.17100824 | E33: =E32/D32-1 -> 0.12706476 | F33: =F32/E32-1 -> 0.089659641 | G33: =G32/F32-1 -> 0.10874998 | H33: =H32/G32-1 -> 0.10703081 | I33: =I32/H32-1 -> 0.10544081
A34: Number of company stores | B34: =B95+B118+B142+B166 -> 10143 | C34: =C95+C118+C142+C166 -> 10713 | D34: =D95+D118+D142+D166 -> 12235 | E34: =E95+E118+E142+E166 -> 12885 | F34: =F95+F118+F142+F166 -> 13535 | G34: =G95+G118+G142+G166 -> 14185 | H34: =H95+H118+H142+H166 -> 14835 | I34: =I95+I118+I142+I166 -> 15485
A35: Revenues/Average Store | B35: 1.0071914 | C35: =C32/((B34+C34)/2) -> 1.2450134 | D35: =D32/((C34+D34)/2) -> 1.3250131 | E35: =E32/((D34+E34)/2) -> 1.3642509 | F35: =F32/((E34+F34)/2) -> 1.4134223 | G35: =G32/((F34+G34)/2) -> 1.4936373 | H35: =H32/((G34+H34)/2) -> 1.579431 | I35: =I32/((H34+I34)/2) -> 1.6711074
A36: Revenue Growth/Average Store | C36: =C35/B35-1 -> 0.23612394 | D36: =D35/C35-1 -> 0.064256052 | E36: =E35/D35-1 -> 0.02961314 | F36: =F35/E35-1 -> 0.036042777 | G36: =G35/F35-1 -> 0.056752326 | H36: =H35/G35-1 -> 0.05743949 | I36: =I35/H35-1 -> 0.058043937
A39: Licensing | B39: =B72 -> 1351 | C39: =C72 -> 1583.5 | D39: =D72 -> 1856 | E39: =E72 -> 2185.0084 | F39: =F72 -> 2453.965 | G39: =G72 -> 2792.5958 | H39: =H72 -> 3162.0826 | I39: =I72 -> 3565.0297
A40: Growth rates | C40: =C39/B39-1 -> 0.17209474 | D40: =D39/C39-1 -> 0.17208715 | E40: =E39/D39-1 -> 0.17726745 | F40: =F39/E39-1 -> 0.12309178 | G40: =G39/F39-1 -> 0.13799333 | H40: =H39/G39-1 -> 0.13230948 | I40: =I39/H39-1 -> 0.12743089
A41: Number of licensed stores | B41: =B96+B119+B143+B167 -> 9624 | C41: =C96+C119+C143+C167 -> 10653 | D41: =D96+D119+D143+D167 -> 10808 | E41: =E96+E119+E143+E167 -> 11958 | F41: =F96+F119+F143+F167 -> 13108 | G41: =G96+G119+G143+G167 -> 14258 | H41: =H96+H119+H143+H167 -> 15408 | I41: =I96+I119+I143+I167 -> 16558
A42: Revenues/Average Store | B42: 0.11153307 | C42: =C39/((C41+B41)/2) -> 0.15618681 | D42: =D39/((D41+C41)/2) -> 0.17296491 | E42: =E39/((E41+D41)/2) -> 0.19195365 | F42: =F39/((F41+E41)/2) -> 0.19580028 | G42: =G39/((G41+F41)/2) -> 0.20409236 | H42: =H39/((H41+G41)/2) -> 0.2131789 | I42: =I39/((I41+H41)/2) -> 0.22305135
A43: Revenue Growth/Average Store | C43: =C42/B42-1 -> 0.40036325 | D43: =D42/C42-1 -> 0.10742328 | E43: =E42/D42-1 -> 0.10978374 | F43: =F42/E42-1 -> 0.020039397 | G43: =G42/F42-1 -> 0.042349659 | H43: =H42/G42-1 -> 0.044521719 | I43: =I42/H42-1 -> 0.046310605
A46: CPG, Foodservice and Other | B46: =B78 -> 1713.1 | C46: =C78 -> 1881.3 | D46: =D78 -> 2103.5 | E46: =E78 -> 2358.3471 | F46: =F78 -> 2545.235 | G46: =G78 -> 2799.7585 | H46: =H78 -> 3079.7344 | I46: =I78 -> 3387.7078
A47: Growth rates | C47: =C46/B46-1 -> 0.098184578 | D47: =D46/C46-1 -> 0.11810982 | E47: =E46/D46-1 -> 0.12115385 | F47: =F46/E46-1 -> 0.079245283 | G47: =G46/F46-1 -> 0.1 | H47: =H46/G46-1 -> 0.1 | I47: =I46/H46-1 -> 0.1
A50: Revenues | B50: =B32+B39+B46 -> 14866.8 | C50: =C32+C39+C46 -> 16447.8 | D50: =D32+D39+D46 -> 19162.7 | E50: =E32+E39+E46 -> 21678.346 | F50: =F32+F39+F46 -> 23670.508 | G50: =G32+G39+G46 -> 26294.167 | H50: =H32+H39+H46 -> 29159.361 | I50: =I32+I39+I46 -> 32286.726
A54: Starbucks' Combined Revenue Forecasts
...

Sheet Valuation
A1: =Data!A1 -> Financial Statement Analysis Package (FSAP): Version 9.0
A2: =Data!A2 -> Financial Reporting, Financial Statement Analysis, and Valuation: A Strategic Perspective, 9th Edition | L2: FSAP User Guides:
A3: By James Wahlen, Steve Baginski and Mark Bradshaw
L4: The FSAP user should only enter data in the blue-font cells shaded light green.
A6: The FSAP User Guides appear in column L to the right. | L6: A Comment on Entering Valuation Parameter Assumptions:
L7: The FSAP user must enter valuation parameter assumptions in the green-shaded, blue font boxes below. These valuation parameters involve the costs of common equity capital, debt capital, and preferred stock capital (if any), as well as the long run growth rate assumption. FSAP references data in the Data spreadsheet and the Forecasts spreadsheet when available. FSAP uses these parameters to compute costs of capital to use as discount rates in the valuation models.
A8: DATA CHECKS - Estimated Value per Share
A9: Dividend Based Valuation | F9: =E83 -> 66.096015 | L9: FSAP automatically references the estimated value per share.
A10: Free Cash Flow Valuation | F10: =E113 -> 66.096015 | L10: FSAP automatically references the estimated value per share.
A11: Residual Income Valuation | F11: =E170 -> 66.096015 | L11: FSAP automatically references the estimated value per share.
A12: Residual Income Market-to-Book Valuation | F12: =E231 -> 66.096015 | L12: FSAP automatically references the estimated value per share.
A13: Free Cash Flow for All Debt and Equity Valuation | F13: =E267 -> 65.953759 | L13: FSAP automatically references the estimated value per share.
A14: Check: All Estimated Value per Share amounts should be the same, with the possible exception of the share value from the
A15: Free Cash Flow for All Debt and Equity model. See additional comments in cell L266.
A18: FSAP OUTPUT: | C18: VALUATION MODELS
A19: =Data!$A$9 -> Analyst Name: | C19: =Data!$B$9 -> Wahlen, Baginski & Bradshaw
A20: =Data!$A$10 -> Company Name: | C20: =Data!$B$10 -> Starbucks
A22: VALUATION PARAMETER ASSUMPTIONS
L23: Market Value Parameters:
A24: Current share price | F24: =Data!G150 -> 56.84 | L24: FSAP uses the most recent share price entered in the Data spreadsheet. The FSAP user can override this and enter the most recent share price directly in this cell.
A25: Number of shares outstanding | F25: =Data!$G$147 -> 1485.1 | L25: FSAP uses the most recent number of shares outstanding entered in the Data spreadsheet. The FSAP user can override this and enter the most recent number of shares outstanding directly in this cell.
A26: Current market value | F26: =F24*F25 -> 84413.084 | L26: FSAP computes market value of equity using market price per share times number of shares outstanding.
A28: Long-run growth assumption used in forecasts | F28: =Forecasts!$J$15 -> 0.03 | L28: Long Run Growth Parameters:
A29: Long-run growth assumption used in valuation. | F29: 0.03 | L29: Enter the long run growth rate assumption for use in the valuation models. This growth rate must agree with the long run growth rate used to forecast Year +6 and Beyond in the Forecasts spreadsheet.
A30: (Both long-run growth assumptions should be the same.)
A32: COST OF EQUITY CAPITAL: | L32: Cost of Equity Capital Parameters:
A33: Equity risk factor (market beta) | F33: 0.75 | L33: Enter the market beta.
A34: Risk free rate | F34: 0.027 | L34: Enter a risk-free rate of return, such as the yield on 3 to 5 year U.S. Treasury bonds.
A35: Market risk premium | F35: 0.06 | L35: Enter the expected market risk premium. This is the amount by which the average expected rate of return on a diversified portfolio of stocks is expected to exceed the expected rate of return on a portfolio of risk free securities. Reasonable estimates commonly range from 3% to 9%.
A36: Required rate of return on common equity: | F36: =F34+F33*F35 -> 0.072 | L36: Using the above parameters, FSAP computes the expected rate of return on equity using the market model version of the CAPM.
A38: COST OF DEBT CAPITAL | L38: Cost of Debt Capital Parameters:
A39: Debt capital | F39: 2402 | L39: FSAP uses the total amount of short term debt and long term debt from the most recent balance sheet data in the Forecasts worksheet. The analyst can override this default by entering the market value of debt capital, if known.
A40: Cost of debt capital, before tax | F40: =-Forecasts!E63 -> 0.027067164 | L40: FSAP uses the interest rate assumption entered in the Forecasts spreadsheet. The analyst can override this default by entering here the expected interest rate on debt capital to be used in computing the weighted average cost of capital. The interest rate on debt capital used here in valuation should be consistent with the interest rate assumed in the forecasts of future interest expense in the Forecasts Spreadsheet.
A41: Effective tax rate | F41: =Forecasts!E76 -> -0.34 | L41: FSAP uses the tax rate assumption entered in the Forecasts spreadsheet. The analyst can override this default by entering here the effective tax rate for use in computing the effective after-tax cost of debt capital.
A42: After-tax cost of debt capital | F42: =F40*(1+F41) -> 0.017864328 | L42: FSAP uses the above parameters to compute the after-tax cost of debt capital.
A44: COST OF PREFERRED STOCK | L44: Cost of Preferred Stock Parameters:
A45: Preferred stock capital | F45: 0 | L45: FSAP uses the amount of preferred stock entered in the most recent balance sheet data in the Forecasts worksheet. The analyst can override this default by entering the market value of preferred stock, if known.
A46: Preferred dividends | F46: 0 | L46: FSAP uses the preferred stock dividend entered in the Forecasts spreadsheet. The analyst can override this default by entering the required rate of return on preferred stock, if known.
A47: Implied yield | F47: 0 | L47: FSAP uses the above parameters to compute the cost of preferred stock capital.
A49: COST OF NONCONTROLLING INTERESTS' CAPITAL | L49: Cost of Noncontrolling Interests Parameters:
...
